Workbook

Sheet Instructions
A1: Chat British: Practice scenarios (120)
A3: What this is | B3: Practice questions for all 12 categories. Each comes from one approved taxonomy entry. The app uses only rows whose Status is Approved.
A4: How they were made | B4: AI-drafted (Claude) from your approved taxonomy entries. The setup comes from the entry's example and surface markers, the right answer from its Good Response, the wrong answers from the misreadings the entry warns about, and the feedback restates its "What It Actually Means". Legal and statistical details in the entries were left out of the feedback on purpose.
A5: Approval record | B5: All rows are Approved because the founder accepted the whole set. The Review state column records what that means: 24 rows (the original 6 and batch 1) were read and approved individually; the other 96 were accepted in bulk and still need an item-by-item read. Please change Review state to "Reviewed and approved by founder" as you go. Do not remove the column.
A6: Spot-check first | B6: Fifteen of the bulk-approved rows are marked yellow in the Spot-check first column, at least one per category. Reading those first (about 10 minutes) tells you whether the rest need changes.
A7: What to edit | B7: Any text in the blue cells. Set Status to Needs edit or Rejected for anything that shouldn't be shown (it then disappears from the app on the next import). Use Review notes for changes you want but haven't made.
A8: Length | B8: The Longest feedback column turns red above 180 characters. Longer feedback makes the answer panel tall on a phone.
A9: Colour key | B9: Light blue = AI-drafted. Yellow = spot-check first. Grey = reference text from the taxonomy; do not edit.
A10: Columns | B10: Scenario ID is unique and never reused. Norm ID is the taxonomy entry it comes from. The right answer appears in a random position in the app.
A12: Category | B12: In this file | C12: Already in the app | D12: Total | E12: Source of the app figure
A13: Workplace | B13: =COUNTIF(Scenarios!$C$2:$C$601,A13) | C13: 0 | D13: =B13+C13 | E13: All scenarios now live in this workbook.
A14: Healthcare | B14: =COUNTIF(Scenarios!$C$2:$C$601,A14) | C14: 0 | D14: =B14+C14
A15: Housing & landlord | B15: =COUNTIF(Scenarios!$C$2:$C$601,A15) | C15: 0 | D15: =B15+C15
A16: Job search | B16: =COUNTIF(Scenarios!$C$2:$C$601,A16) | C16: 0 | D16: =B16+C16
A17: Social | B17: =COUNTIF(Scenarios!$C$2:$C$601,A17) | C17: 0 | D17: =B17+C17
A18: Admin & bureaucracy | B18: =COUNTIF(Scenarios!$C$2:$C$601,A18) | C18: 0 | D18: =B18+C18
A19: Education | B19: =COUNTIF(Scenarios!$C$2:$C$601,A19) | C19: 0 | D19: =B19+C19
A20: Dating & relationships | B20: =COUNTIF(Scenarios!$C$2:$C$601,A20) | C20: 0 | D20: =B20+C20
A21: Money & transactions | B21: =COUNTIF(Scenarios!$C$2:$C$601,A21) | C21: 0 | D21: =B21+C21
A22: Transport & commuting | B22: =COUNTIF(Scenarios!$C$2:$C$601,A22) | C22: 0 | D22: =B22+C22
A23: Neighbours & community | B23: =COUNTIF(Scenarios!$C$2:$C$601,A23) | C23: 0 | D23: =B23+C23
A24: Customer service & retail | B24: =COUNTIF(Scenarios!$C$2:$C$601,A24) | C24: 0 | D24: =B24+C24
A25: Total | B25: =SUM(B13:B24) | C25: =SUM(C13:C24) | D25: =SUM(D13:D24)

Sheet Scenarios
A1: Scenario ID | B1: Norm ID | C1: Category | D1: Setup | E1: Prompt | F1: Right answer | G1: Right-answer feedback | H1: Wrong answer 1 | I1: Wrong 1 feedback | J1: Wrong answer 2 | K1: Wrong 2 feedback | L1: Status | M1: Review state | N1: Spot-check first | O1: Review notes | P1: Longest feedback (chars) | Q1: Entry: What It Actually Means | R1: Entry: Good Response
A2: SC-WP-2-a | B2: WP-2-promotion-discussion-indirectness | C2: Workplace | D2: You ask your manager about a promotion. She says, “It's definitely something we can look at.” No date is mentioned. | E2: What do you do? | F2: Ask to set a date to revisit it, and what she'd want to see from you before then. | G2: Warm language isn't a promise. A real commitment usually comes with a date or a documented next step. | H2: Take it as a near-term commitment and wait. | I2: It's a deferral, not a promise. With no date attached, nothing is actually in motion. | J2: Drop the subject so you don't seem pushy. | K2: Asking for a concrete next step is normal. Dropping it leaves a vague deferral vague. | L2: Approved | M2: Bulk-approved by founder; item review pending | P2: =MAX(LEN(G2),LEN(I2),LEN(K2)) | Q2: Not a promise — it's a deferral. A real commitment usually comes with a specific date or documented next step, not just warm language. | R2: Ask for something concrete: "Could we set a specific date to revisit this, and what would you want to see from me before then?"
A3: SC-WP-4-a | B3: WP-4-deadline-reminder-escalation | C3: Workplace | D3: Your manager emails: “Just a gentle reminder about the report.” Three days later: “Following up again on this.” You haven't sent it yet. | E3: How do you read the second email? | F3: As rising urgency. Treat the task as a priority now. | G3: Repetition is the real signal. Each “gentle” reminder means urgency is rising, however mild it sounds. | H3: As routine politeness. There's still no rush. | I3: The wording stays polite, but a second follow-up on the same task is a priority signal. | J3: Wait for a third reminder before acting. | K3: The third is usually direct, such as “I need this by end of day”. Don't wait for it. | L3: Approved | M3: Bulk-approved by founder; item review pending | N3: Yes | P3: =MAX(LEN(G3),LEN(I3),LEN(K3)) | Q3: Each repeated "gentle" reminder signals rising urgency, even though the wording stays polite — treat repetition itself as the real signal. | R3: Treat any second follow-up on the same task as a priority signal, regardless of how mild the wording still sounds.
A4: SC-WP-6-a | B4: WP-6-agreement-in-meetings-silence | C4: Workplace | D4: You present a plan in a team meeting. Everyone nods and says it could work. Nobody pushes back. | E4: What do you do next? | F4: Check with key people one by one: “Any concerns before I move ahead?” | G4: Real objections are often saved for a private conversation, so agreement in the room can be provisional. | H4: Treat it as settled and go ahead. | I4: Agreement in the room can be provisional. Concerns often arrive later, in private. | J4: Ask the whole group again if anyone disagrees. | K4: People rarely voice objections in front of the group. A private follow-up invites them. | L4: Approved | M4: Bulk-approved by founder; item review pending | P4: =MAX(LEN(G4),LEN(I4),LEN(K4)) | Q4: Real objections are often saved for a private, one-on-one follow-up rather than voiced in front of the group — the meeting-room agreement can be provisional, not final. | R4: After a meeting where a decision was made, follow up individually with key people: “Any concerns before I move ahead with this?” — invites private pushback before it's too late to change course.
A5: SC-WP-7-a | B5: WP-7-cc-escalation-email | C5: Workplace | D5: In a routine email chain about a project, a colleague suddenly CCs your manager. There's no explanation and the tone stays friendly. | E5: What does the CC most likely mean? | F5: The issue is being put on record. Ask plainly if there's a concern to address. | G5: A sudden CC often marks the point an issue is formally tracked, even when the tone stays friendly. | H5: Nothing. It's just keeping people in the loop. | I5: With no explanation, a new CC usually means the sender wants it on record. | J5: A friendly gesture to share credit. | K5: The friendly tone can mislead. A new CC with no explanation more often signals escalation. | L5: Approved | M5: Bulk-approved by founder; item review pending | P5: =MAX(LEN(G5),LEN(I5),LEN(K5)) | Q5: This often marks the point an issue is being formally tracked or escalated, even though the email's tone may stay friendly and unchanged. | R5: When newly CC'd people appear, ask plainly: “Just flagging — is there a concern here I should be addressing directly?”
A6: SC-WP-8-a | B6: WP-8-sorry-to-bother-request | C6: Workplace | D6: Your manager says: “Sorry to bother you, this is probably nothing, but could you rewrite the report by end of day?” | E6: How big is the ask? | F6: As big as it sounds: a full rewrite, due today. | G6: The apology softens the tone, not the size or urgency. Take the request itself at face value. | H6: Small. They said it's probably nothing. | I6: The “probably nothing” is politeness. A same-day rewrite is a substantial request. | J6: Fine to do later in the week. | K6: The deadline in the request is real, whatever the soft opening says. | L6: Approved | M6: Bulk-approved by founder; item review pending | P6: =MAX(LEN(G6),LEN(I6),LEN(K6)) | Q6: The apology softens the tone of the request but doesn't reflect its actual size or urgency — take the request itself at face value, not the apology. | R6: Treat the substance of the ask, not the softening language, as the real signal of urgency and size.
A7: SC-WP-10-a | B7: WP-10-feedback-sandwich | C7: Workplace | D7: Your manager says: “Great presentation. Maybe tighten the data section next time, but overall really well done.” | E7: What's the main thing to take from this? | F7: The data section needs work. Repeat it back to confirm. | G7: The critical point often sits in the middle: short in words, but not small in importance. | H7: That it went really well and nothing needs changing. | I7: That misses the middle comment, which is often the real point of the feedback. | J7: That your manager thought the whole presentation was weak. | K7: That's an overreaction. The specific point is the data section, not the whole presentation. | L7: Approved | M7: Bulk-approved by founder; item review pending | P7: =MAX(LEN(G7),LEN(I7),LEN(K7)) | Q7: The middle comment is often the actual, most important point of the feedback — proportionally small wording doesn't mean proportionally small importance. | R7: When feedback includes a “middle” point, repeat it back to confirm: “So the main thing to work on is the data section — got it.”
A8: SC-WP-12-a | B8: WP-12-calendar-invite-formality | C8: Workplace | D8: After weeks of casual chat messages, your manager sends a calendar invite with a specific title and agenda for the same topic. | E8: How do you approach the meeting? | F8: Prepare as for a formal conversation. | G8: Moving from chat to a scheduled invite is itself a signal the matter is being taken more seriously. | H8: Treat it as routine and go in unprepared. | I8: An invite for a topic normally handled informally is a shift. Assuming it's routine misses it. | J8: Ask to keep it as an informal chat instead. | K8: The formal invite was a deliberate choice. Preparing for it is the safer reading. | L8: Approved | M8: Bulk-approved by founder; item review pending | P8: =MAX(LEN(G8),LEN(I8),LEN(K8)) | Q8: The shift from informal chat to a scheduled invite is itself a signal the matter is being taken more seriously or formally than before. | R8: When an invite appears for a topic normally handled informally, prepare as if for a formal conversation rather than assuming it's purely routine.
A9: SC-WP-13-a | B9: WP-13-not-the-right-forum | C9: Workplace | D9: In a team meeting you raise a budget concern. The lead replies, “This might not be the right forum for that.” | E9: What do you do? | F9: Follow up directly afterwards: “Could we find 15 minutes to go through the budget point?” | G9: It usually means they don't want to address it in front of the group, not that the point is wrong. | H9: Wait for them to bring it up again. | I9: Without a follow-up from you, it usually never comes back. | J9: Assume the budget concern doesn't matter. | K9: It's the venue they're avoiding, not the issue. A direct follow-up gets it heard. | L9: Approved | M9: Bulk-approved by founder; item review pending | P9: =MAX(LEN(G9),LEN(I9),LEN(K9)) | Q9: This usually means the person doesn't want to address the point in front of the group, not that the venue is genuinely wrong. | R9: Follow up directly and specifically afterward: "Could we find 15 minutes to go through the budget point from earlier?" rather than waiting for the other person to raise it again.
A10: SC-WP-15-a | B10: WP-15-meeting-jargon-deferral | C10: Workplace | D10: A colleague loves your idea in a meeting. The lead says, “Let's park that for now.” No date or owner is mentioned. | E10: What do you do? | F10: Ask for a next step on the spot: “Who should bring this back, and roughly when?” | G10: Without a concrete next step, a parked topic often quietly drops. | H10: Assume it will be revisited soon. | I10: It usually isn't, unless someone owns it and a date is set. | J10: Take it as a polite no and forget it. | K10: It may not be a no. Asking for an owner and a date finds out. | L10: Approved | M10: Bulk-approved by founder; item review pending | P10: =MAX(LEN(G10),LEN(I10),LEN(K10)) | Q10: Without a concrete next step attached, "parking" a topic often means it quietly drops rather than genuinely pausing. | R10: When something is parked, ask for a concrete next step on the spot: "Who should own bringing this back, and roughly when?"
A11: SC-HC-2-a | B11: HC-2-referral-wait-silence | C11: Healthcare | D11: Six weeks after a GP referral you've heard nothing. The letter said, “We'll be in touch once it's been reviewed.” | E11: What do you do? | F11: Call the surgery or referral line to check the status. | G11: Long waits reflect NHS process and backlog, not a dropped case. Asking is normal and expected. | H11: Assume the request was lost, and give up. | I11: Silence is common and doesn't mean your case was dropped. Checking is how you find out. | J11: Wait quietly, since calling would be rude. | K11: It isn't rude. Calling to check status is normal and expected. | L11: Approved | M11: Bulk-approved by founder; item review pending | P11: =MAX(LEN(G11),LEN(I11),LEN(K11)) | Q11: This reflects NHS process/backlog, not that the case was dropped — the official standard is 18 weeks from referral to treatment, but as of 2026 only around two-thirds of patients are actually being seen within that window nationally, so a longer wait is common, not exceptional. | R11: Call the GP surgery or hospital referral line directly to check status rather than assuming; this is normal and expected, not rude to ask.
A12: SC-HC-3-a | B12: HC-3-nhs-111-triage-language | C12: Healthcare | D12: You phone 111 about a minor problem. The call ends with a long list: “If you get any of these symptoms, go to A&E immediately.” | E12: How do you read the list? | F12: As standard safety wording. Ask how urgent your case is specifically. | G12: It's standard safety wording given to nearly everyone, not a specific escalation of your case. | H12: As a sign your case is more serious than they said. | I12: That's the common panic. The list is given to almost everyone. | J12: As something to ignore completely. | K12: Better to ask: “How urgent is this specifically?” That tells you what it means for you. | L12: Approved | M12: Bulk-approved by founder; item review pending | P12: =MAX(LEN(G12),LEN(I12),LEN(K12)) | Q12: This is defensive, standardized safety language given to nearly everyone, not a specific escalation of concern about your individual case. | R12: Ask directly: “Based on what I've told you, how urgent is this specifically?” rather than reading the standard safety list as a signal.
A13: SC-HC-4-a | B13: HC-4-pharmacist-first-point-of-contact | C13: Healthcare | D13: You ring the surgery about a sore throat. The receptionist says, “Try the pharmacy first.” | E13: What does that mean? | F13: A standard route for minor issues. If symptoms persist, ask for a GP appointment. | G13: For minor issues it's an expected referral, not the surgery deflecting or downgrading your concern. | H13: That the surgery is brushing you off. | I13: It's a standard route for minor conditions, not a dismissal. | J13: That you should never see a GP for this. | K13: Not never. If symptoms persist after the pharmacy, that's the natural point to ask for a GP. | L13: Approved | M13: Bulk-approved by founder; item review pending | P13: =MAX(LEN(G13),LEN(I13),LEN(K13)) | Q13: This is a standard, expected referral for minor issues (rashes, coughs, UTIs, etc.), not the surgery deflecting or downgrading the concern. | R13: Treat a pharmacist referral as a genuine, appropriate option — and if symptoms persist after, that's the natural point to request a GP appointment.
A14: SC-HC-5-a | B14: HC-5-patient-advocating-for-self | C14: Healthcare | D14: Your GP appointment is nearly over. The doctor says briefly, “Anything else?” You have a second, worrying symptom you haven't mentioned. | E14: What do you do? | F14: Say it directly: “Yes, there's one more thing I want to cover.” | G14: The system expects you to raise what matters. Staying quiet out of politeness reads as “nothing else”. | H14: Say “No, that's all” so you don't take up their time. | I14: That's read as nothing else, and the appointment ends without your main concern. | J14: Hint at it and hope the doctor picks up on it. | K14: A hint usually isn't picked up. State what matters directly and early. | L14: Approved | M14: Bulk-approved by founder; item review pending | P14: =MAX(LEN(G14),LEN(I14),LEN(K14)) | Q14: The system expects the patient to raise what matters to them proactively; staying quiet out of politeness or deference is read as “nothing else,” not as holding back out of respect. | R14: Prepare your 1-2 main points beforehand and state them directly and early: “There are two things I want to cover today: X and Y.”
A15: SC-HC-8-a | B15: HC-8-watchful-waiting-approach | C15: Healthcare | D15: For a minor symptom the GP says, “Let's give it two weeks and see how it settles.” No tests or referral are offered. | E15: What do you do? | F15: Ask what signs would mean coming back sooner than two weeks. | G15: It's a deliberate strategy for conditions that often settle on their own, not a sign your concern is unimportant. | H15: Conclude the GP isn't taking you seriously. | I15: Waiting and reviewing is standard practice for many minor conditions. | J15: Don't go back at all unless it gets much worse. | K15: The plan depends on you returning if it hasn't improved, so ask what to watch for. | L15: Approved | M15: Bulk-approved by founder; item review pending | P15: =MAX(LEN(G15),LEN(I15),LEN(K15)) | Q15: This is a deliberate, evidence-based strategy for self-limiting conditions, not a sign the GP thinks the concern is unimportant. | R15: Ask directly what to watch for and when to return: "What specific signs would mean I should come back sooner than two weeks?"
A16: SC-HC-9-a | B16: HC-9-econsult-online-triage-form | C16: Healthcare | D16: You ring your surgery and are told, “Please fill in the online form instead.” | E16: How do you take it? | F16: As the standard route. Use the form, and be specific and complete. | G16: It's the surgery's standard way of managing demand, not a barrier set against your request. | H16: As a brush-off. Keep ringing until someone answers. | I16: The form is how requests are normally triaged, often faster than expected. | J16: Fill it in with just a few words to save time. | K16: Be specific and complete. A detailed form is easier to triage properly. | L16: Approved | M16: Bulk-approved by founder; item review pending | N16: Yes | P16: =MAX(LEN(G16),LEN(I16),LEN(K16)) | Q16: This is the surgery's standard triage process for managing demand, not a barrier placed specifically in front of this particular request. | R16: Use the online form as the primary channel and be specific and complete in it, since it's often triaged faster than expected.
A17: SC-HC-10-a | B17: HC-10-same-day-urgent-only-gatekeeping | C17: Healthcare | D17: You call for an appointment and the receptionist asks, “Can I ask what it's regarding, so I can see who's best to help?” You feel embarrassed. | E17: What do you do? | F17: Answer factually and specifically, including how long you've had it. | G17: It's a standard triage question asked of everyone, not a test of whether your concern is valid. | H17: Refuse to say, since it's private. | I17: The question is routine. Answering helps route you to the right type of appointment. | J17: Stay vague so you don't seem to be fussing. | K17: Specifics get you routed faster. A vague answer makes the right appointment harder to pick. | L17: Approved | M17: Bulk-approved by founder; item review pending | P17: =MAX(LEN(G17),LEN(I17),LEN(K17)) | Q17: This question is a standard triage step for every patient, not scrutiny of whether this specific concern is valid. | R17: Answer the triage question factually and specifically, including how long the issue has lasted, to get routed to the right appointment type faster.
A18: SC-HC-11-a | B18: HC-11-ae-triage-wait-times | C18: Healthcare | D18: At A&E a nurse sees you briefly, then you wait in the main waiting area for hours with no update. | E18: What does the long wait most likely mean? | F18: You've been assessed as less urgent than others. It's fine to ask for a rough update. | G18: A long wait after triage usually means lower urgency compared with others, not that you were overlooked. | H18: That you've been forgotten. | I18: You've been assessed. Asking the desk for a rough update is acceptable. | J18: That something is seriously wrong and nobody is telling you. | K18: The opposite is more likely. More urgent cases are seen first. | L18: Approved | M18: Bulk-approved by founder; item review pending | P18: =MAX(LEN(G18),LEN(I18),LEN(K18)) | Q18: A long wait after initial triage typically confirms the case has been assessed as lower urgency relative to others being treated, not that it was overlooked. | R18: It's acceptable to ask the desk for a rough update after a long wait: "Just checking I'm still in the queue — any sense of how much longer?"
A19: SC-HC-15-a | B19: HC-15-second-opinion-request-phrasing | C19: Healthcare | D19: You want a second opinion on a diagnosis, but it feels rude to say so to your GP. | E19: What do you say? | F19: “I'd like a second opinion. Could you point me toward how to arrange that?” | G19: A plain request is acceptable. Softening is a politeness habit, not a sign you shouldn't ask. | H19: “Is there anyone else I could possibly speak to?” and leave it there. | I19: The hedged version can go unnoticed. Say plainly that you want a second opinion. | J19: Wait a few weeks, then try again. | K19: Delay doesn't help. It's a normal, accepted request, so make it plainly now. | L19: Approved | M19: Bulk-approved by founder; item review pending | P19: =MAX(LEN(G19),LEN(I19),LEN(K19)) | Q19: This is a normal, accepted request even when phrased softly — the hedging is a politeness convention, not a sign the patient shouldn't ask. | R19: It's acceptable to state the request plainly: "I'd like to get a second opinion on this — could you point me toward how to arrange that?"
A20: SC-HL-2-a | B20: HL-2-passive-aggressive-written-notice | C20: Housing & landlord | D20: Your neighbour leaves a note: “Just a friendly reminder about bin day, hope you don't mind me asking.” It's the third note. | E20: How do you read it? | F20: As a firm complaint. Respond to the practical issue directly. | G20: The politeness is a buffer. The underlying message is a firm complaint, not a casual suggestion. | H20: As a casual suggestion you can leave for now. | I20: A repeated “friendly” note means the issue isn't casual. | J20: As a joke between neighbours. | K20: Nothing playful. The soft wording hides a real complaint, so deal with the practical issue. | L20: Approved | M20: Bulk-approved by founder; item review pending | P20: =MAX(LEN(G20),LEN(I20),LEN(K20)) | Q20: The politeness is a social buffer — the underlying message is a firm complaint, not a casual suggestion. | R20: Treat the specific ask as the real message regardless of the soft wording, and respond to the practical issue directly.
A21: SC-HL-3-a | B21: HL-3-inventory-check-in-formality | C21: Housing & landlord | D21: When you move in, the landlord hands you a long inventory listing every mark and scuff, and seems keen to have it signed quickly. | E21: What do you do? | F21: Check it thoroughly, and add notes and photos for anything inaccurate before signing. | G21: The inventory is your main protection against unfair deposit deductions later. | H21: Sign quickly to seem agreeable. | I21: Rushing is how people end up unable to dispute a deduction for a mark that was already there. | J21: Skip it, since a long list is excessive. | K21: It isn't excessive. Skipping a careful read works against your own interest. | L21: Approved | M21: Bulk-approved by founder; item review pending | P21: =MAX(LEN(G21),LEN(I21),LEN(K21)) | Q21: This document is the tenant's main protection against unfair deposit deductions later — treating it as excessive or skipping a careful read works against the tenant's own interest. | R21: Take time to check the inventory thoroughly and add notes/photos for anything inaccurate before signing, regardless of how quick the landlord seems to want it done.
A22: SC-HL-6-a | B22: HL-6-shared-house-kitchen-etiquette-notes | C22: Housing & landlord | D22: A note appears on the fridge: “Can everyone please remember to wash up their own dishes :)” You've left a few plates. | E22: How do you read the note? | F22: As the end of a build-up. Respond promptly, in person if you can. | G22: By the time a note appears, the issue has usually been building for a while. | H22: As a light, general reminder. | I22: The smiley is friendly, but it's rarely the first time it has bothered someone. | J22: As aimed at someone else, so ignore it. | K22: Notes like this rarely come from nowhere. A prompt, direct response beats hoping it's about someone else. | L22: Approved | M22: Bulk-approved by founder; item review pending | P22: =MAX(LEN(G22),LEN(I22),LEN(K22)) | Q22: By the time a note appears, the issue has likely been building for a while — it's rarely the first time it's bothered someone. | R22: Respond to a shared-space note promptly and directly, and consider a brief in-person acknowledgment: “Sorry, I'll sort that — let me know if it's been an ongoing issue.”
A23: SC-HL-7-a | B23: HL-7-viewing-feedback-silence | C23: Housing & landlord | D23: After a flat viewing the agent says, “We'll let you know.” Two weeks pass with no contact. | E23: What do you do? | F23: Treat it as a likely no, keep viewing other flats, and follow up once politely. | G23: Silence past the expected time functions as the rejection. An explicit “no” is uncommon. | H23: Keep waiting. They said they'd let you know. | I23: That's how people miss other options. Silence past the timeframe is usually the answer. | J23: Phone every day until you get a clear answer. | K23: One polite follow-up is enough. Meanwhile keep looking at other properties. | L23: Approved | M23: Bulk-approved by founder; item review pending | P23: =MAX(LEN(G23),LEN(I23),LEN(K23)) | Q23: Silence past the expected timeframe functions as the rejection in UK rental practice — an explicit “no” is uncommon. | R23: Treat silence past the stated timeframe as a likely no and keep actively viewing other properties in parallel, following up once politely for a final answer.
A24: SC-HL-8-a | B24: HL-8-referencing-in-progress-delay | C24: Housing & landlord | D24: You've applied for a flat. For over a week the agent keeps saying, “Referencing is still being processed, we'll update you as soon as we hear.” | E24: What do you do? | F24: Ask which reference is outstanding, and offer to help chase it. | G24: Referencing depends on outside providers replying, which is often the real bottleneck. | H24: Assume you've been rejected. | I24: A slow previous landlord or employer can hold things up without any rejection. | J24: Keep waiting without asking. | K24: A specific question gets further: which reference is outstanding, and can you help? | L24: Approved | M24: Bulk-approved by founder; item review pending | P24: =MAX(LEN(G24),LEN(I24),LEN(K24)) | Q24: Referencing depends on external providers (employers, previous landlords, credit agencies) responding, which is often the actual bottleneck, not agent inaction. | R24: Ask specifically which part of referencing is outstanding: "Is there a particular reference we're still waiting on that I could help chase?"
A25: SC-HL-12-a | B25: HL-12-income-affordability-multiplier | C25: Housing & landlord | D25: A letting agent says your income must be at least a set multiple of the rent. Yours is just below, but you have strong savings. | E25: What do you do? | F25: Ask whether savings or a larger upfront payment could be offered instead. | G25: The multiplier is a standard formula, not a judgement of you. Alternatives are worth asking about. | H25: Take it as a rejection and stop pursuing this flat. | I25: It's a uniform formula, not a verdict on you. Asking about alternatives costs nothing. | J25: Argue that the rule is unfair. | K25: The formula is applied to everyone. Offering a concrete alternative is the better route. | L25: Approved | M25: Bulk-approved by founder; item review pending | P25: =MAX(LEN(G25),LEN(I25),LEN(K25)) | Q25: This is a standardized formula applied uniformly, not a judgment about this specific applicant's overall financial reliability — and since the Renters' Rights Act 2025, it's now unlawful for a landlord or agent to refuse an otherwise-qualifying applicant, or make renting harder for them, because they receive benefits or have children (councils can fine up to £7,000 for breaching this). | R25: If income is close to the threshold, ask directly whether savings or a larger upfront payment can be offered as an alternative to meeting the multiplier exactly.
A26: SC-HL-14-a | B26: HL-14-permitted-occupiers-clause | C26: Housing & landlord | D26: Your partner has been staying with you for a few months. The tenancy lists named occupiers only. The landlord seemed relaxed when you mentioned it casually. | E26: What do you do? | F26: Ask for a written update to the agreement. | G26: A relaxed landlord doesn't override the written clause. A long-term guest needs formal agreement. | H26: Rely on the landlord's friendly reaction. | I26: A casual OK isn't a written change, and a long stay can still breach the clause. | J26: Say nothing, since nobody has complained. | K26: Silence leaves the clause breached. Beyond a couple of weeks, ask for it in writing. | L26: Approved | M26: Bulk-approved by founder; item review pending | P26: =MAX(LEN(G26),LEN(I26),LEN(K26)) | Q26: A landlord being personally relaxed in conversation doesn't override the written clause — a guest staying long-term can still be a genuine breach if not addressed formally. | R26: For any guest staying beyond a couple of weeks, request a written update to the agreement rather than relying on a verbal heads-up.
A27: SC-HL-15-a | B27: HL-15-break-clause-deferral | C27: Housing & landlord | D27: You ask your landlord to let you leave a few months early. He says, “Let me check with the agency and get back to you.” Nothing follows. | E27: What do you do? | F27: Ask for an answer by a specific date, since you need to plan. | G27: It may be a genuine step, but it can also buy time. A deadline moves things forward. | H27: Wait for them to come back to you. | I27: Waiting leaves it open-ended. A date makes a reply, or a refusal, harder to avoid. | J27: Take the silence as permission to leave. | K27: Silence isn't agreement. Ask for a clear answer by a date you name. | L27: Approved | M27: Bulk-approved by founder; item review pending | P27: =MAX(LEN(G27),LEN(I27),LEN(K27)) | Q27: This may be a genuine process step, but it can also be a way of buying time or softening a refusal. Since May 2026, most tenancies are periodic from the start, and a tenant can generally end one by giving at least two months' written notice, without needing a landlord's agreement at all. | R27: Set a specific follow-up date when asking: "Could you let me know by [date] either way, since I need to plan my next steps?"
A28: SC-HL-16-a | B28: HL-16-end-of-tenancy-cleaning-checklist | C28: Housing & landlord | D28: Before moving out you clean the whole flat thoroughly yourself. The inventory mentions a “professional clean” standard. | E28: What do you do? | F28: Check the exact cleaning clause, and book a professional clean with a receipt if it asks for one. | G28: Your own cleaning may not meet the contract's standard, however clean the flat looks. | H28: Rely on your own deep clean. | I28: Without the professional service and receipt, the cleaning standard may still not be met. | J28: Ask the landlord to judge it by eye. | K28: The contract sets the standard, not how the flat looks. Check the exact clause first. | L28: Approved | M28: Bulk-approved by founder; item review pending | N28: Yes | P28: =MAX(LEN(G28),LEN(I28),LEN(K28)) | Q28: A tenant's own thorough cleaning may not meet the specific contractual standard unless a professional service and receipt are provided, regardless of how clean the property looks. | R28: Check the tenancy agreement's exact cleaning clause before moving out, and book a professional clean with a receipt if that's what's specified.
A29: SC-JS-2-a | B29: JS-2-salary-negotiation-indirectness | C29: Job search | D29: In a first interview they ask, “What's your expected salary range?” before mentioning any number. | E29: What do you do? | F29: Give a confident, well-researched range. | G29: It's a negotiation norm. Stating a researched range is expected, not pushy. | H29: Say “I'm flexible, whatever you think is fair.” | I29: A vague answer leaves you without a position and can read as unprepared. | J29: Say you'd rather not talk about money yet. | K29: It's a routine question here. Deflecting it reads as unprepared. | L29: Approved | M29: Bulk-approved by founder; item review pending | P29: =MAX(LEN(G29),LEN(I29),LEN(K29)) | Q29: This is a negotiation norm, not evasiveness — giving a well-researched range in response is expected and normal, not pushy. | R29: Research the market range beforehand and state a confident range when asked, rather than deflecting the question.
A30: SC-JS-3-a | B30: JS-3-cv-personal-statement-understatement | C30: Job search | D30: Your CV is full of words like “exceptional” and “outstanding”. UK recruiters give polite but cool feedback. | E30: What do you change? | F30: Lead with specific, factual results: numbers and concrete outcomes. | G30: Understated, evidence-led writing reads as credible. Heavy self-promotion can read as less so. | H30: Make the claims even stronger to stand out. | I30: In some UK sectors, extreme self-promotion can read as less credible. | J30: Remove your achievements to look modest. | K30: Modesty doesn't mean hiding results. Let the numbers carry the weight, not the adjectives. | L30: Approved | M30: Bulk-approved by founder; item review pending | P30: =MAX(LEN(G30),LEN(I30),LEN(K30)) | Q30: Understated language is not a lack of confidence in this context — being extremely self-promotional can actually read as less credible in some UK sectors, particularly traditional or public-sector ones. | R30: Lead with specific, factual outcomes (numbers, concrete results) rather than superlative language — let the evidence carry the weight instead of the adjectives.
A31: SC-JS-4-a | B31: JS-4-recruiter-warm-language-non-commitment | C31: Job search | D31: A recruiter tells you, “You're a really strong candidate, the client loved you.” No next step or date is mentioned. | E31: How do you read it? | F31: As friendly encouragement. Ask for the next formal step and when you'll hear. | G31: It's standard relationship-management language, not a reliable signal of where you stand. | H31: As a near-certain offer. | I31: Warmth isn't commitment. Many candidates hear this and don't get an offer. | J31: As a lie to ignore. | K31: It isn't a lie, just routine warmth. Ask what the next formal step is and by when. | L31: Approved | M31: Bulk-approved by founder; item review pending | P31: =MAX(LEN(G31),LEN(I31),LEN(K31)) | Q31: This is standard relationship-management language recruiters use with most candidates to keep them engaged, not a reliable signal of where you stand. | R31: Ask directly for concrete next steps and timelines rather than reading warmth as commitment: “What's the next formal step, and by when should I expect to hear?”
A32: SC-JS-5-a | B32: JS-5-competency-question-structure-expectation | C32: Job search | D32: In an interview you're asked, “Tell me about a time you had to deal with a difficult colleague.” The interviewer waits. | E32: How do you answer? | F32: Give a specific example: the situation, your task, what you did and the result. | G32: A structured, specific past example is what's being assessed. | H32: Explain your general approach: “I always try to communicate well.” | I32: A general philosophy reads as unprepared. | J32: Say you've never had a difficult colleague. | K32: That doesn't answer the question. Prepare real examples in advance. | L32: Approved | M32: Bulk-approved by founder; item review pending | P32: =MAX(LEN(G32),LEN(I32),LEN(K32)) | Q32: A vague or general answer (“I always try to communicate well”) reads as unprepared — a specific, structured past example is what's actually being assessed. | R32: Prepare 4-5 specific past examples in advance, structured as situation → task → action → result, ready to adapt to different competency questions.
A33: SC-JS-6-a | B33: JS-6-notice-period-negotiation-norm | C33: Job search | D33: In an interview they ask, “When could you start?” You have a month's notice at your current job. | E33: What do you say? | F33: State your real notice period, and add that you're keen to start as soon as it allows. | G33: Employers plan around standard notice periods. Honesty here is the norm, not a risk. | H33: Say you can start immediately, to seem keen. | I33: A shorter-than-normal answer isn't needed to show keenness. | J33: Avoid answering until you have an offer. | K33: It's a routine question. A plain answer with some enthusiasm works better. | L33: Approved | M33: Bulk-approved by founder; item review pending | P33: =MAX(LEN(G33),LEN(I33),LEN(K33)) | Q33: Employers expect and plan around a standard notice period; a shorter-than-normal answer isn't required to demonstrate keenness, and honesty here is the norm, not a risk. | R33: State the real notice period plainly and, if genuinely relevant, add a brief note of enthusiasm: “My notice period is one month, but I'm very keen to start as soon as that allows.”
A34: SC-JS-7-a | B34: JS-7-networking-coffee-informality | C34: Job search | D34: A senior contact in your field says, “Would you fancy a coffee sometime to chat about the sector?” | E34: How do you treat it? | F34: As a real opportunity. Prepare a few relevant points or questions. | G34: It's a standard, taken-seriously way to build a professional relationship. | H34: As purely social, so go without preparing. | I34: It's informal in tone but not in purpose. Prepare as you would for a formal meeting. | J34: As vague politeness that probably won't happen. | K34: It's a genuine invitation. Treat it as a real conversation. | L34: Approved | M34: Bulk-approved by founder; item review pending | P34: =MAX(LEN(G34),LEN(I34),LEN(K34)) | Q34: This is a standard, taken-seriously way to build a professional relationship or explore an opportunity informally — showing up prepared and treating it as a real conversation is expected, not just small talk. | R34: Treat an informal coffee/chat invitation from a professional contact as a real opportunity — prepare a few relevant points or questions, same as for a formal meeting.
A35: SC-JS-8-a | B35: JS-8-keep-cv-on-file-soft-rejection | C35: Job search | D35: After an unsuccessful interview the email ends: “We'll keep your CV on file for future opportunities.” | E35: What does that mean? | F35: The process has ended. If you're interested later, follow up in a few months. | G35: It's a polite way to close without an explicit “no”, not a commitment to revisit you. | H35: That they'll contact you when a role comes up. | I35: Don't wait to be contacted. The phrase usually ends that process. | J35: That the decision is still open. | K35: It isn't. Treat this process as over, and follow up yourself if you want future roles. | L35: Approved | M35: Bulk-approved by founder; item review pending | P35: =MAX(LEN(G35),LEN(I35),LEN(K35)) | Q35: This phrase functions as a polite way to end the conversation without an explicit "no," rather than a genuine commitment to revisit the application later. | R35: Treat this phrase as the end of that specific process, and if genuinely interested in future roles, proactively follow up in a few months rather than waiting to be contacted.
A36: SC-JS-12-a | B36: JS-12-finalizing-internally-offer-delay | C36: Job search | D36: After a verbal job offer, the employer says, “We're just waiting on some internal sign-off.” No date is given. | E36: What do you do? | F36: Ask roughly when to expect the formal offer. | G36: Such delays are usually administrative, not a sign the decision is still undecided. | H36: Assume the offer is being withdrawn. | I36: It's most often approvals and paperwork. Anxious guessing doesn't help. | J36: Wait quietly and say nothing. | K36: Asking for a timeframe is fine, and it gets you something concrete. | L36: Approved | M36: Bulk-approved by founder; item review pending | P36: =MAX(LEN(G36),LEN(I36),LEN(K36)) | Q36: This delay is most often administrative (approvals, paperwork) rather than a sign the decision itself is still genuinely undecided. | R36: Ask for a specific timeframe rather than waiting anxiously: "That's great to hear — roughly when should I expect the formal offer through?"
A37: SC-JS-15-a | B37: JS-15-meet-the-team-informal-framing | C37: Job search | D37: Before a final stage you're told, “It's just an informal chat to meet the team, no pressure.” | E37: How do you approach it? | F37: Prepare as for a formal interview, with questions and examples ready. | G37: Team members are usually asked for feedback afterwards, so the chat is genuinely assessed. | H37: Relax completely and go without preparing. | I37: The casual framing is real, but the feedback it produces counts. | J37: Treat it as a pure social event and avoid talking about work. | K37: It's assessed even if it doesn't feel like an interview, so have questions and examples ready. | L37: Approved | M37: Bulk-approved by founder; item review pending | N37: Yes | P37: =MAX(LEN(G37),LEN(I37),LEN(K37)) | Q37: Team members are typically asked for feedback afterward regardless of the casual framing, so the conversation is genuinely assessed even if it doesn't feel like a formal interview. | R37: Prepare for an "informal" meeting stage with the same care as a formal interview — have a few questions and examples ready, even if the tone in the room is relaxed.
A38: SC-SO-3-a | B38: SO-3-queueing-norm-enforcement | C38: Social | D38: In a bakery, a loose group of people stands near the counter. You can't tell whether it's a queue. | E38: What do you do? | F38: Ask, “Sorry, is this the end of the queue?” | G38: It's a completely normal question. Queue order is taken seriously as a matter of fairness. | H38: Walk to the front of the group. | I38: That prompts visible disapproval. Queueing is taken seriously. | J38: Stand nearby and watch to work out who's next. | K38: Asking directly is normal and expected. Guessing risks stepping out of order. | L38: Approved | M38: Bulk-approved by founder; item review pending | P38: =MAX(LEN(G38),LEN(I38),LEN(K38)) | Q38: Queue order is taken seriously as a matter of fairness, and a correction — even a mild one — reflects a real social expectation, not an overreaction. | R38: When uncertain whether a group is queueing, ask directly: “Sorry, is this the end of the queue?” — a completely normal and expected question.
A39: SC-SO-4-a | B39: SO-4-small-talk-weather-function | C39: Social | D39: A shopkeeper says, “Terrible weather we're having, isn't it?” | E39: How do you answer? | F39: Briefly agree: “I know, awful, isn't it!” | G39: It's a greeting ritual to set a friendly tone, not a real question about the weather. | H39: Give your detailed view of the forecast. | I39: A long answer to a ritual remark comes across as oddly serious. | J39: Say nothing, since it isn't really a question. | K39: The reply is part of the greeting. A brief agreement keeps the tone friendly. | L39: Approved | M39: Bulk-approved by founder; item review pending | N39: Yes | P39: =MAX(LEN(G39),LEN(I39),LEN(K39)) | Q39: This is a social ritual to establish a friendly tone, not a genuine request for detailed opinion or information about the weather. | R39: A brief, light agreement (“I know, awful, isn't it!”) is the expected response — treat it as a greeting, not a real question.
A40: SC-SO-5-a | B40: SO-5-punctuality-for-social-events | C40: Social | D40: You're invited to a friend's casual dinner for 7pm. You arrive at exactly 7pm and the host is still cooking. | E40: What would have been better? | F40: Arriving 10 to 15 minutes after the stated time. | G40: For casual home events the time is treated as approximate. Formal and work events are different. | H40: Arriving even earlier, to help. | I40: Earlier makes it worse. Hosts often aren't ready on the dot. | J40: Arriving an hour late, to be safe. | K40: Too far. About 10 to 15 minutes after is the usual margin for a casual invitation. | L40: Approved | M40: Bulk-approved by founder; item review pending | P40: =MAX(LEN(G40),LEN(I40),LEN(K40)) | Q40: For casual social events specifically (not formal or work-related ones), the stated time is often treated as approximate rather than fixed — arriving exactly on time can occasionally catch a host still getting ready. | R40: For clearly informal social invitations, treat the stated time as approximate and consider arriving 10-15 minutes after — though always exactly on time for anything formal or work-related.
...
